WARNING:werkzeug: * Running on all addresses.
   WARNING: This is a development server. Do not use it in a production deployment.
INFO:werkzeug: * Running on http://10.0.159.6:5000/ (Press CTRL+C to quit)
ERROR:b:Exception on /login [GET]
Traceback (most recent call last):
  File "C:\Users\Admin\AppData\Local\Programs\Python\Python310\lib\site-packages\sqlalchemy\engine\base.py", line 1802, in _execute_context
    self.dialect.do_execute(
  File "C:\Users\Admin\AppData\Local\Programs\Python\Python310\lib\site-packages\sqlalchemy\engine\default.py", line 732, in do_execute
    cursor.execute(statement, parameters)
sqlite3.OperationalError: no such column: users.api_acc

The above exception was the direct cause of the following exception:

Traceback (most recent call last):
  File "C:\Users\Admin\AppData\Local\Programs\Python\Python310\lib\site-packages\flask\app.py", line 2073, in wsgi_app
    response = self.full_dispatch_request()
  File "C:\Users\Admin\AppData\Local\Programs\Python\Python310\lib\site-packages\flask\app.py", line 1518, in full_dispatch_request
    rv = self.handle_user_exception(e)
  File "C:\Users\Admin\AppData\Local\Programs\Python\Python310\lib\site-packages\flask\app.py", line 1516, in full_dispatch_request
    rv = self.dispatch_request()
  File "C:\Users\Admin\AppData\Local\Programs\Python\Python310\lib\site-packages\flask\app.py", line 1502, in dispatch_request
    return self.ensure_sync(self.view_functions[rule.endpoint])(**req.view_args)
  File "C:\Users\Admin\Desktop\binance\b.py", line 159, in login
    return render_template('login.html')
  File "C:\Users\Admin\AppData\Local\Programs\Python\Python310\lib\site-packages\flask\templating.py", line 146, in render_template
    ctx.app.update_template_context(context)
  File "C:\Users\Admin\AppData\Local\Programs\Python\Python310\lib\site-packages\flask\app.py", line 756, in update_template_context
    context.update(func())
  File "C:\Users\Admin\AppData\Local\Programs\Python\Python310\lib\site-packages\flask_login\utils.py", line 379, in _user_context_processor
    return dict(current_user=_get_user())
  File "C:\Users\Admin\AppData\Local\Programs\Python\Python310\lib\site-packages\flask_login\utils.py", line 346, in _get_user
    current_app.login_manager._load_user()
  File "C:\Users\Admin\AppData\Local\Programs\Python\Python310\lib\site-packages\flask_login\login_manager.py", line 318, in _load_user
    user = self._user_callback(user_id)
  File "C:\Users\Admin\Desktop\binance\b.py", line 81, in load_user
    return db_sess.query(User).get(user_id)
  File "<string>", line 2, in get
  File "C:\Users\Admin\AppData\Local\Programs\Python\Python310\lib\site-packages\sqlalchemy\util\deprecations.py", line 401, in warned
    return fn(*args, **kwargs)
  File "C:\Users\Admin\AppData\Local\Programs\Python\Python310\lib\site-packages\sqlalchemy\orm\query.py", line 943, in get
    return self._get_impl(ident, loading.load_on_pk_identity)
  File "C:\Users\Admin\AppData\Local\Programs\Python\Python310\lib\site-packages\sqlalchemy\orm\query.py", line 947, in _get_impl
    return self.session._get_impl(
  File "C:\Users\Admin\AppData\Local\Programs\Python\Python310\lib\site-packages\sqlalchemy\orm\session.py", line 2892, in _get_impl
    return db_load_fn(
  File "C:\Users\Admin\AppData\Local\Programs\Python\Python310\lib\site-packages\sqlalchemy\orm\loading.py", line 530, in load_on_pk_identity
    session.execute(
  File "C:\Users\Admin\AppData\Local\Programs\Python\Python310\lib\site-packages\sqlalchemy\orm\session.py", line 1692, in execute
    result = conn._execute_20(statement, params or {}, execution_options)
  File "C:\Users\Admin\AppData\Local\Programs\Python\Python310\lib\site-packages\sqlalchemy\engine\base.py", line 1614, in _execute_20
    return meth(self, args_10style, kwargs_10style, execution_options)
  File "C:\Users\Admin\AppData\Local\Programs\Python\Python310\lib\site-packages\sqlalchemy\sql\elements.py", line 325, in _execute_on_connection
    return connection._execute_clauseelement(
  File "C:\Users\Admin\AppData\Local\Programs\Python\Python310\lib\site-packages\sqlalchemy\engine\base.py", line 1481, in _execute_clauseelement
    ret = self._execute_context(
  File "C:\Users\Admin\AppData\Local\Programs\Python\Python310\lib\site-packages\sqlalchemy\engine\base.py", line 1845, in _execute_context
    self._handle_dbapi_exception(
  File "C:\Users\Admin\AppData\Local\Programs\Python\Python310\lib\site-packages\sqlalchemy\engine\base.py", line 2026, in _handle_dbapi_exception
    util.raise_(
  File "C:\Users\Admin\AppData\Local\Programs\Python\Python310\lib\site-packages\sqlalchemy\util\compat.py", line 207, in raise_
    raise exception
  File "C:\Users\Admin\AppData\Local\Programs\Python\Python310\lib\site-packages\sqlalchemy\engine\base.py", line 1802, in _execute_context
    self.dialect.do_execute(
  File "C:\Users\Admin\AppData\Local\Programs\Python\Python310\lib\site-packages\sqlalchemy\engine\default.py", line 732, in do_execute
    cursor.execute(statement, parameters)
sqlalchemy.exc.OperationalError: (sqlite3.OperationalError) no such column: users.api_acc
[SQL: SELECT users.id AS users_id, users.api_acc AS users_api_acc, users.email AS users_email, users.api AS users_api, users.secret AS users_secret 
FROM users 
WHERE users.id = ?]
[parameters: ('40',)]
(Background on this error at: https://sqlalche.me/e/14/e3q8)
INFO:werkzeug:192.168.1.7 - - [05/Feb/2023 12:48:55] "[35m[1mGET /login HTTP/1.1[0m" 500 -
ERROR:b:Exception on /login [GET]
Traceback (most recent call last):
  File "C:\Users\Admin\AppData\Local\Programs\Python\Python310\lib\site-packages\sqlalchemy\engine\base.py", line 1802, in _execute_context
    self.dialect.do_execute(
  File "C:\Users\Admin\AppData\Local\Programs\Python\Python310\lib\site-packages\sqlalchemy\engine\default.py", line 732, in do_execute
    cursor.execute(statement, parameters)
sqlite3.OperationalError: no such column: users.api_acc

The above exception was the direct cause of the following exception:

Traceback (most recent call last):
  File "C:\Users\Admin\AppData\Local\Programs\Python\Python310\lib\site-packages\flask\app.py", line 2073, in wsgi_app
    response = self.full_dispatch_request()
  File "C:\Users\Admin\AppData\Local\Programs\Python\Python310\lib\site-packages\flask\app.py", line 1518, in full_dispatch_request
    rv = self.handle_user_exception(e)
  File "C:\Users\Admin\AppData\Local\Programs\Python\Python310\lib\site-packages\flask\app.py", line 1516, in full_dispatch_request
    rv = self.dispatch_request()
  File "C:\Users\Admin\AppData\Local\Programs\Python\Python310\lib\site-packages\flask\app.py", line 1502, in dispatch_request
    return self.ensure_sync(self.view_functions[rule.endpoint])(**req.view_args)
  File "C:\Users\Admin\Desktop\binance\b.py", line 159, in login
    return render_template('login.html')
  File "C:\Users\Admin\AppData\Local\Programs\Python\Python310\lib\site-packages\flask\templating.py", line 146, in render_template
    ctx.app.update_template_context(context)
  File "C:\Users\Admin\AppData\Local\Programs\Python\Python310\lib\site-packages\flask\app.py", line 756, in update_template_context
    context.update(func())
  File "C:\Users\Admin\AppData\Local\Programs\Python\Python310\lib\site-packages\flask_login\utils.py", line 379, in _user_context_processor
    return dict(current_user=_get_user())
  File "C:\Users\Admin\AppData\Local\Programs\Python\Python310\lib\site-packages\flask_login\utils.py", line 346, in _get_user
    current_app.login_manager._load_user()
  File "C:\Users\Admin\AppData\Local\Programs\Python\Python310\lib\site-packages\flask_login\login_manager.py", line 318, in _load_user
    user = self._user_callback(user_id)
  File "C:\Users\Admin\Desktop\binance\b.py", line 81, in load_user
    return db_sess.query(User).get(user_id)
  File "<string>", line 2, in get
  File "C:\Users\Admin\AppData\Local\Programs\Python\Python310\lib\site-packages\sqlalchemy\util\deprecations.py", line 401, in warned
    return fn(*args, **kwargs)
  File "C:\Users\Admin\AppData\Local\Programs\Python\Python310\lib\site-packages\sqlalchemy\orm\query.py", line 943, in get
    return self._get_impl(ident, loading.load_on_pk_identity)
  File "C:\Users\Admin\AppData\Local\Programs\Python\Python310\lib\site-packages\sqlalchemy\orm\query.py", line 947, in _get_impl
    return self.session._get_impl(
  File "C:\Users\Admin\AppData\Local\Programs\Python\Python310\lib\site-packages\sqlalchemy\orm\session.py", line 2892, in _get_impl
    return db_load_fn(
  File "C:\Users\Admin\AppData\Local\Programs\Python\Python310\lib\site-packages\sqlalchemy\orm\loading.py", line 530, in load_on_pk_identity
    session.execute(
  File "C:\Users\Admin\AppData\Local\Programs\Python\Python310\lib\site-packages\sqlalchemy\orm\session.py", line 1692, in execute
    result = conn._execute_20(statement, params or {}, execution_options)
  File "C:\Users\Admin\AppData\Local\Programs\Python\Python310\lib\site-packages\sqlalchemy\engine\base.py", line 1614, in _execute_20
    return meth(self, args_10style, kwargs_10style, execution_options)
  File "C:\Users\Admin\AppData\Local\Programs\Python\Python310\lib\site-packages\sqlalchemy\sql\elements.py", line 325, in _execute_on_connection
    return connection._execute_clauseelement(
  File "C:\Users\Admin\AppData\Local\Programs\Python\Python310\lib\site-packages\sqlalchemy\engine\base.py", line 1481, in _execute_clauseelement
    ret = self._execute_context(
  File "C:\Users\Admin\AppData\Local\Programs\Python\Python310\lib\site-packages\sqlalchemy\engine\base.py", line 1845, in _execute_context
    self._handle_dbapi_exception(
  File "C:\Users\Admin\AppData\Local\Programs\Python\Python310\lib\site-packages\sqlalchemy\engine\base.py", line 2026, in _handle_dbapi_exception
    util.raise_(
  File "C:\Users\Admin\AppData\Local\Programs\Python\Python310\lib\site-packages\sqlalchemy\util\compat.py", line 207, in raise_
    raise exception
  File "C:\Users\Admin\AppData\Local\Programs\Python\Python310\lib\site-packages\sqlalchemy\engine\base.py", line 1802, in _execute_context
    self.dialect.do_execute(
  File "C:\Users\Admin\AppData\Local\Programs\Python\Python310\lib\site-packages\sqlalchemy\engine\default.py", line 732, in do_execute
    cursor.execute(statement, parameters)
sqlalchemy.exc.OperationalError: (sqlite3.OperationalError) no such column: users.api_acc
[SQL: SELECT users.id AS users_id, users.api_acc AS users_api_acc, users.email AS users_email, users.api AS users_api, users.secret AS users_secret 
FROM users 
WHERE users.id = ?]
[parameters: ('40',)]
(Background on this error at: https://sqlalche.me/e/14/e3q8)
INFO:werkzeug:192.168.1.7 - - [05/Feb/2023 12:48:56] "[35m[1mGET /login HTTP/1.1[0m" 500 -
ERROR:b:Exception on / [GET]
Traceback (most recent call last):
  File "C:\Users\Admin\AppData\Local\Programs\Python\Python310\lib\site-packages\sqlalchemy\engine\base.py", line 1802, in _execute_context
    self.dialect.do_execute(
  File "C:\Users\Admin\AppData\Local\Programs\Python\Python310\lib\site-packages\sqlalchemy\engine\default.py", line 732, in do_execute
    cursor.execute(statement, parameters)
sqlite3.OperationalError: no such column: users.api_acc

The above exception was the direct cause of the following exception:

Traceback (most recent call last):
  File "C:\Users\Admin\AppData\Local\Programs\Python\Python310\lib\site-packages\flask\app.py", line 2073, in wsgi_app
    response = self.full_dispatch_request()
  File "C:\Users\Admin\AppData\Local\Programs\Python\Python310\lib\site-packages\flask\app.py", line 1518, in full_dispatch_request
    rv = self.handle_user_exception(e)
  File "C:\Users\Admin\AppData\Local\Programs\Python\Python310\lib\site-packages\flask\app.py", line 1516, in full_dispatch_request
    rv = self.dispatch_request()
  File "C:\Users\Admin\AppData\Local\Programs\Python\Python310\lib\site-packages\flask\app.py", line 1502, in dispatch_request
    return self.ensure_sync(self.view_functions[rule.endpoint])(**req.view_args)
  File "C:\Users\Admin\Desktop\binance\b.py", line 102, in index
    return render_template('index.html')
  File "C:\Users\Admin\AppData\Local\Programs\Python\Python310\lib\site-packages\flask\templating.py", line 146, in render_template
    ctx.app.update_template_context(context)
  File "C:\Users\Admin\AppData\Local\Programs\Python\Python310\lib\site-packages\flask\app.py", line 756, in update_template_context
    context.update(func())
  File "C:\Users\Admin\AppData\Local\Programs\Python\Python310\lib\site-packages\flask_login\utils.py", line 379, in _user_context_processor
    return dict(current_user=_get_user())
  File "C:\Users\Admin\AppData\Local\Programs\Python\Python310\lib\site-packages\flask_login\utils.py", line 346, in _get_user
    current_app.login_manager._load_user()
  File "C:\Users\Admin\AppData\Local\Programs\Python\Python310\lib\site-packages\flask_login\login_manager.py", line 318, in _load_user
    user = self._user_callback(user_id)
  File "C:\Users\Admin\Desktop\binance\b.py", line 81, in load_user
    return db_sess.query(User).get(user_id)
  File "<string>", line 2, in get
  File "C:\Users\Admin\AppData\Local\Programs\Python\Python310\lib\site-packages\sqlalchemy\util\deprecations.py", line 401, in warned
    return fn(*args, **kwargs)
  File "C:\Users\Admin\AppData\Local\Programs\Python\Python310\lib\site-packages\sqlalchemy\orm\query.py", line 943, in get
    return self._get_impl(ident, loading.load_on_pk_identity)
  File "C:\Users\Admin\AppData\Local\Programs\Python\Python310\lib\site-packages\sqlalchemy\orm\query.py", line 947, in _get_impl
    return self.session._get_impl(
  File "C:\Users\Admin\AppData\Local\Programs\Python\Python310\lib\site-packages\sqlalchemy\orm\session.py", line 2892, in _get_impl
    return db_load_fn(
  File "C:\Users\Admin\AppData\Local\Programs\Python\Python310\lib\site-packages\sqlalchemy\orm\loading.py", line 530, in load_on_pk_identity
    session.execute(
  File "C:\Users\Admin\AppData\Local\Programs\Python\Python310\lib\site-packages\sqlalchemy\orm\session.py", line 1692, in execute
    result = conn._execute_20(statement, params or {}, execution_options)
  File "C:\Users\Admin\AppData\Local\Programs\Python\Python310\lib\site-packages\sqlalchemy\engine\base.py", line 1614, in _execute_20
    return meth(self, args_10style, kwargs_10style, execution_options)
  File "C:\Users\Admin\AppData\Local\Programs\Python\Python310\lib\site-packages\sqlalchemy\sql\elements.py", line 325, in _execute_on_connection
    return connection._execute_clauseelement(
  File "C:\Users\Admin\AppData\Local\Programs\Python\Python310\lib\site-packages\sqlalchemy\engine\base.py", line 1481, in _execute_clauseelement
    ret = self._execute_context(
  File "C:\Users\Admin\AppData\Local\Programs\Python\Python310\lib\site-packages\sqlalchemy\engine\base.py", line 1845, in _execute_context
    self._handle_dbapi_exception(
  File "C:\Users\Admin\AppData\Local\Programs\Python\Python310\lib\site-packages\sqlalchemy\engine\base.py", line 2026, in _handle_dbapi_exception
    util.raise_(
  File "C:\Users\Admin\AppData\Local\Programs\Python\Python310\lib\site-packages\sqlalchemy\util\compat.py", line 207, in raise_
    raise exception
  File "C:\Users\Admin\AppData\Local\Programs\Python\Python310\lib\site-packages\sqlalchemy\engine\base.py", line 1802, in _execute_context
    self.dialect.do_execute(
  File "C:\Users\Admin\AppData\Local\Programs\Python\Python310\lib\site-packages\sqlalchemy\engine\default.py", line 732, in do_execute
    cursor.execute(statement, parameters)
sqlalchemy.exc.OperationalError: (sqlite3.OperationalError) no such column: users.api_acc
[SQL: SELECT users.id AS users_id, users.api_acc AS users_api_acc, users.email AS users_email, users.api AS users_api, users.secret AS users_secret 
FROM users 
WHERE users.id = ?]
[parameters: ('40',)]
(Background on this error at: https://sqlalche.me/e/14/e3q8)
INFO:werkzeug:192.168.1.7 - - [05/Feb/2023 12:48:59] "[35m[1mGET / HTTP/1.1[0m" 500 -
